Workbook

Sheet Laporan Keuangan
A1: PT MEDIKA UTAMA SEJAHTERA (RS MEDIKA UTAMA) - LAPORAN LABA RUGI KOMERSIAL
A2: Kode Akun | B2: Nama Akun / Pos Keuangan | C2: Nilai Komersial (Rp) | D2: Catatan & Perlakuan Fiskal
A3: 4-1100 | B3: Pendapatan Rawat Inap & Tindakan Medis | C3: 45000000000 | D3: Objek Non-PPN (Jasa Kesehatan / JKP Bebas)
A4: 4-1200 | B4: Pendapatan Farmasi, Obat, & Alkes | C4: 32000000000 | D4: Objek PPN Mix (Rawat Inap Bebas vs Rawat Jalan Terutang)
A5: 4-1300 | B5: Pendapatan Klaim BPJS Kesehatan | C5: 28500000000 | D5: Akrual Layanan BPJS Kesehatan
A6: 4-1400 | B6: Pendapatan Sewa Kantin & Area Komersial | C6: 1500000000 | D6: Objek PPh Final Pasal 4(2)
B7: TOTAL PENDAPATAN | C7: =SUM(C3:C6) -> 107000000000 | D7: Total Peredaran Usaha Komersial
A8: 5-1100 | B8: Beban Jasa Medis Dokter (Tetap & Mitra) | C8: 18500000000 | D8: Objek PPh 21 Dokter (Terindikasi Selisih Ekualisasi)
A9: 5-1200 | B9: Beban Pokok Obat & Bahan Medis Habis Pakai (BMHP) | C9: 22000000000 | D9: PPN Masukan Pembelian Farmasi
A10: 5-1300 | B10: Beban Gaji & Tunjangan Pegawai Non-Medis | C10: 14000000000 | D10: Objek PPh 21 Pegawai Tetap
A11: 73171 | B11: Beban Pemeliharaan & Kalibrasi Alkes | C11: 2400000000 | D11: Objek PPh 23 (Kalibrasi MRI/CT-Scan)
A12: 109695 | B12: Beban Catering Inap & Gizi Pasien | C12: 2200000000 | D12: Objek PPh 23 / PPN Jasa Catering
A13: 146219 | B13: Beban Kebersihan, Keamanan, & Limbah B3 | C13: 1800000000 | D13: Objek PPh 23 (Pengolahan Medwaste)
A14: 438413 | B14: Beban Penyusutan Bangunan & Peralatan Medis | C14: 4800000000 | D14: Beda Waktu Depresiasi Fiskal vs Komersial
A15: 474938 | B15: Beban Cadangan Penurunan Nilai Piutang BPJS | C15: 2200000000 | D15: Non-Deductible Expense (Koreksi Fiskal Positif)
A16: 511462 | B16: Beban Natura, Tempat Tinggal & Mobil Dokter | C16: 1450000000 | D16: Objek PMK-66/2023 (Koreksi Fiskal Positif)
A17: 767132 | B17: Beban Operasional Lain-lain & Administrasi | C17: 24850000000 | D17: Operational Costs Komersial
B18: TOTAL BEBAN OPERASIONAL | C18: =SUM(C8:C17) -> 94200000000 | D18: Total Beban Usaha Komersial
B20: LABA BERSIH KOMERSIAL | C20: =C7-C18 -> 12800000000 | D20: Laba Bersih Komersial Sebelum Pajak
A22: B. NERACA RINGKAS (PER 31 DESEMBER 2025)
A23: Kode Akun | B23: Pos Neraca / Akun | C23: Nilai (Rp) | D23: Catatan / Klasifikasi
A24: 1-1000 | B24: ASET LANCAR
A25: 1-1100 | B25: Kas & Bank | C25: 8500000000 | D25: Kas & Setara Kas
A26: 1-1200 | B26: Piutang Klaim BPJS Kesehatan | C26: 6800000000 | D26: Piutang Pelayanan Medis BPJS
A27: 1-1300 | B27: Persediaan Obat & BMHP | C27: 5400000000 | D27: Persediaan Farmasi & Medis
B29: Total Aset Lancar | C29: =SUM(C25:C27) -> 20700000000 | D29: Subtotal Aset Lancar
A30: 36526 | B30: ASET TETAP
A31: 73051 | B31: Tanah & Bangunan | C31: 42000000000 | D31: Nilai Perolehan Properti & Gedung
A32: 109575 | B32: Peralatan Medis | C32: 28000000000 | D32: Nilai Perolehan Alat Kesehatan Medis
A33: 146099 | B33: Akumulasi Penyusutan | C33: -16200000000 | D33: Kontra Akun Akumulasi Penyusutan
B35: Total Aset Tetap (Nilai Buku) | C35: =SUM(C31:C33) -> 53800000000 | D35: Subtotal Nilai Buku Aset Tetap
B36: TOTAL ASET | C36: =C29+C35 -> 74500000000 | D36: Grand Total Aset RS Medika
A37: 2-1000 | B37: KEWAJIBAN JANGKA PENDEK (LIABILITAS)
A38: 2-1100 | B38: Utang Usaha | C38: 6200000000 | D38: Utang Vendor & Pemasok BMHP
A39: 2-1200 | B39: Utang PPh 21 | C39: 1150000000 | D39: Utang Pajak PPh 21 Pegawai & Dokter
A40: 2-1300 | B40: Utang PPh 23 | C40: 120000000 | D40: Utang Pajak Jasa & Sewa
A41: 2-1400 | B41: Utang PPN | C41: 4800000000 | D41: Utang Pajak PPN Farmasi / Penyerahan BKP
B42: Total Kewajiban Jangka Pendek | C42: =SUM(C38:C41) -> 12270000000 | D42: Subtotal Kewajiban Lancar
A43: 3-1000 | B43: EKUITAS
A44: 3-1100 | B44: Modal Disetor | C44: 50000000000 | D44: Modal Ditempatkan dan Disetor Penuh
...

Sheet Sub-Ledger PPh 21 Dokter
A1: PT MEDIKA UTAMA SEJAHTERA (RS MEDIKA UTAMA)
A2: SUB-LEDGER PPH PASAL 21 DOKTER - TAHUN PAJAK 2025
A3: Kode Dokter | B3: Nama Dokter & Spesialisasi | C3: Status Kepegawaian | D3: Metode Pemotongan | E3: Penghasilan Bruto (Rp) | F3: Fasilitas Top-Up / Natura (Rp) | G3: Dasar Pengenaan Pajak / DPP (Rp) | H3: PPh 21 Terutang (Rp) | I3: Catatan & Keterangan Kepatuhan Pajak
A4: D-001 | B4: Dr. Budi Santoso, Sp.B | C4: Mitra | D4: Bukan Pegawai Berkesinambungan | E4: 1440000000 | F4: 45000000 | G4: 118800000 | H4: 108000000 | I4: Dokter Spesialis Bedah Mitra (Top-up tempat tinggal dinas)
A5: D-002 | B5: Dr. Siti Aminah, Sp.A | C5: Tetap | D5: Pegawai Tetap (TER PMK-168) | E5: 960000000 | F5: 0 | G5: 124800000 | H5: 124800000 | I5: Dokter Tetap RS, pemotongan TER bulanan PMK-168/2023
A6: D-003 | B6: Dr. Hendra, Sp.OG | C6: Mitra | D6: Bukan Pegawai Berkesinambungan | E6: 2100000000 | F6: 0 | G6: 183750000 | H6: 157500000 | I6: Dokter Spesialis Obgyn Mitra volume tindakan tinggi
A7: D-004 | B7: Dr. Grace, Sp.KK | C7: Mitra | D7: Bukan Pegawai Berkesinambungan | E7: 680000000 | F7: 60000000 | G7: 44400000 | H7: 34000000 | I7: Dokter Mitra Poli Kulit (Top-up fasilitas mobil operasional)
A8: D-005 | B8: Dr. Rahmat, Sp.PD | C8: Tamu | D8: Bukan Pegawai Tidak Berkesinambungan | E8: 520000000 | F8: 28600000 | G8: 26000000 | H8: 26000000 | I8: Dokter Tamu Konsulen (Top-up akomodasi)
A10: TOTAL | B10: REKAPITULASI SUB-LEDGER PPH 21 DOKTER | E10: =SUM(E4:E8) -> 5700000000 | F10: =SUM(F4:F8) -> 133600000 | G10: =SUM(G4:G8) -> 497750000 | H10: =SUM(H4:H8) -> 450300000 | I10: Total Potongan PPh 21 Dokter Terdaftar
A12: RINGKASAN EKUALISASI BEBAN DOKTER VS SUB-LEDGER
A13: Beban Jasa Medis Dokter di Laba Rugi (Kode 5-1100) | C13: ='Laporan Keuangan'!C8 -> 18500000000 | D13: Keterangan Selisih: | E13: Sebagian jasa medis dokter dibayarkan secara kolektif/pihak ketiga atau dokter mitra lain belum masuk sampel sub-ledger.
A14: Total Bruto Dokter Sub-Ledger (5 Dokter Sampel) | C14: =E10 -> 5700000000 | D14: Status Audit: | E14: Perluasan sampling daftar nominatif dokter sebelum pelaporan SPT Tahunan Badan.
A15: Selisih Ekualisasi Beban vs Sub-Ledger | C15: ='Laporan Keuangan'!C8-E10 -> 12800000000 | D15: Rekomendasi: | E15: Ekualisasi menyeluruh 100% dokter mitra & rekonsiliasi bukti potong bupot 21.
A16: Total PPh 21 Dokter Dipotong | C16: =H10 -> 450300000 | D16: Kepatuhan Setor: | E16: Pencocokan dengan akun Utang PPh 21 di Neraca ('Laporan Keuangan'!C39).

Sheet Sub-Ledger PPN Farmasi
A1: PT MEDIKA UTAMA SEJAHTERA (RS MEDIKA UTAMA)
A2: SUB-LEDGER PPN INSTALASI FARMASI & PENYERAHAN OBAT - DESEMBER 2025
A3: Kode Transaksi | B3: Unit Pelayanan / Instalasi | C3: Deskripsi Transaksi / Barang | D3: Nilai Transaksi / DPP (Rp) | E3: Status Faktur Pajak | F3: Tarif PPN | G3: PPN Terutang (Rp) | H3: Status Kepatuhan & Risiko Fiskal
A4: RX-202512-001 | B4: Rawat Inap | C4: Obat Paket Perawatan Rawat Inap | D4: 45000000 | E4: Bebas PPN (080) | F4: 0 | G4: 0 | H4: Patuh (Bebas PPN Fasilitas Layanan Medis)
A5: RX-202512-002 | B5: Rawat Jalan Resep | C5: Obat Resep Poliklinik Dokter Sp. | D5: 28000000 | E5: Bebas PPN (080) | F5: 0 | G5: 0 | H5: Patuh (Bebas PPN Resep Pasien Rajal)
A6: RX-202512-003 | B6: Rawat Jalan Non-Resep | C6: Obat Bebas OTC / Penjualan Bebas | D6: 18000000 | E6: Belum Diterbitkan (HIGH RISK) | F6: 0.11 | G6: =D6*F6 -> 1980000 | H6: HIGH RISK (Objek PPN Belum Terbit Faktur Pajak)
A7: RX-202512-004 | B7: Skincare / Estetika | C7: Alkes & Kosmetika Estetika Medis | D7: 12000000 | E7: Terutang PPN (010) | F7: 0.11 | G7: =D7*F7 -> 1320000 | H7: Patuh (Faktur Pajak 010 Telah Terbit & Dipungut)
A8: RX-202512-005 | B8: Rawat Inap BPJS | C8: BMHP & Obat Paket BPJS Kesehatan | D8: 85000000 | E8: Bebas PPN (080) | F8: 0 | G8: 0 | H8: Patuh (Bebas PPN Paket Perawatan BPJS)
A10: TOTAL | B10: REKAPITULASI SAMPEL TRANSAKSI FARMASI | D10: =SUM(D4:D8) -> 188000000 | G10: =SUM(G4:G8) -> 3300000 | H10: Total Transaksi & Potensi Beban PPN
A12: RINGKASAN REKAPITULASI & EKUALISASI PPN FARMASI
A13: Penyerahan Bebas PPN (Faktur 080 - Rawat Inap & Resep Poliklinik) | D13: =SUMIFS(D4:D8, E4:E8, "Bebas PPN (080)") -> 158000000 | E13: Fasilitas Bebas PPN | G13: 0 | H13: Patuh (Jasa/Obat Medis Bebas PPN)
A14: Penyerahan Terutang PPN Sudah Terbit Faktur (Faktur 010 - Skincare) | D14: =SUMIFS(D4:D8, E4:E8, "Terutang PPN (010)") -> 12000000 | E14: PPN Keluaran Terbit | G14: =SUMIFS(G4:G8, E4:E8, "Terutang PPN (010)") -> 1320000 | H14: Patuh (Faktur Pajak 010 Telah Terbit)
A15: Penyerahan Terutang Belum Terbit Faktur (Obat Bebas OTC - HIGH RISK) | D15: =SUMIFS(D4:D8, E4:E8, "Belum Diterbitkan (HIGH RISK)") -> 18000000 | E15: Potensi Kurang Bayar PPN | G15: =SUMIFS(G4:G8, E4:E8, "Belum Diterbitkan (HIGH RISK)") -> 1980000 | H15: HIGH RISK (Exposure Pajak Terutang)
A16: Total Exposure PPN Farmasi (Terbit Faktur + Belum Terbit OTC) | D16: =D14+D15 -> 30000000 | E16: Total Exposure PPN Terutang | G16: =G14+G15 -> 3300000 | H16: Segera Terbitkan Faktur Pajak 010 OTC
A18: KETERKAITAN DENGAN LAPORAN KEUANGAN TAHUN 2025
A19: Pendapatan Farmasi, Obat, & Alkes di Laba Rugi (Kode Akun 4-1200) | D19: ='Laporan Keuangan'!C4 -> 32000000000 | E19: Nilai Penjualan Komersial Tahunan | H19: Rekonsiliasi omzet farmasi komersial vs SPT PPN
A20: Saldo Utang PPN pada Neraca Komersial (Kode Akun 2-1400) | D20: ='Laporan Keuangan'!C41 -> 4800000000 | E20: Kewajiban PPN Akumulasi di Neraca | H20: Pencocokan SPT Masa PPN Jan-Des 2025

Sheet Sub-Ledger PPh 23 Vendor
A1: PT MEDIKA UTAMA SEJAHTERA (RS MEDIKA UTAMA)
A2: SUB-LEDGER PPH PASAL 23 ATAS JASA VENDOR & REKANAN - TAHUN 2025
A3: Nomor Faktur / Invoice | B3: Nama Vendor / Rekanan Jasa | C3: Deskripsi Transaksi Jasa Medis / Non-Medis | D3: Nilai Tagihan Bruto / DPP (Rp) | E3: Tarif PPh 23 | F3: PPh 23 Terutang / Dipotong (Rp) | G3: Status Kepatuhan Pemotongan | H3: Tingkat Risiko Fiskal | I3: Tindak Lanjut & Rekomendasi Audit
A4: INV-2025-012 | B4: PT Kalibrasi Alkes Nusantara | C4: Maintenance & Kalibrasi MRI / CT-Scan | D4: 150000000 | E4: 0.02 | F4: =D4*E4 -> 3000000 | G4: Belum Dipotong (HIGH RISK) | H4: Tinggi (Kurang Potong Pajak) | I4: Potong PPh 23 saat pembayaran atau buat bupot susulan
A5: INV-2025-089 | B5: PT Catering Sehat Medika | C5: Jasa Catering Pasien Rawat Inap & Gizi | D5: 2200000000 | E5: 0.02 | F5: =D5*E5 -> 44000000 | G5: Dipotong 2% (Compliant) | H5: Rendah (Telah Terbit Bupot) | I5: Bukti potong terbit, ekualisasi cocok dengan Laba Rugi
A6: INV-2025-104 | B6: CV EcoLimbah B3 Medika | C6: Jasa Pengolahan & Pemusnahan Limbah Medis B3 | D6: 650000000 | E6: 0.02 | F6: =D6*E6 -> 13000000 | G6: Belum Dipotong (HIGH RISK) | H6: Tinggi (Kurang Potong Pajak) | I6: Klarifikasi tagihan medwaste & terbitkan bupot PPh 23
A7: INV-2025-210 | B7: PT Secure Guard Indonesia | C7: Jasa Pengamanan Gedung & Instalasi RS | D7: 1150000000 | E7: 0.02 | F7: =D7*E7 -> 23000000 | G7: Dipotong 2% (Compliant) | H7: Rendah (Telah Terbit Bupot) | I7: Bukti potong terbit, cocok dengan beban komersial
A9: TOTAL | B9: REKAPITULASI SAMPEL JASA VENDOR PPH 23 | D9: =SUM(D4:D7) -> 4150000000 | F9: =SUM(F4:F7) -> 83000000 | I9: Total Kewajiban PPh 23 Jasa Vendor
G10: , | H10: ,
A11: RINGKASAN KEPATUHAN & RISIKO AUDIT PPH 23 VENDOR
A12: Kategori Telah Dipotong (Compliant - Catering & Security) | D12: =SUMIFS(D4:D7, G4:G7, "Dipotong 2% (Compliant)") -> 3350000000 | E12: PPh 23 Dipotong Sah | F12: =SUMIFS(F4:F7, G4:G7, "Dipotong 2% (Compliant)") -> 67000000 | G12: Compliant | H12: Rendah | I12: Bukti potong terbit & telah dilaporkan
A13: Kategori Belum Dipotong (HIGH RISK - Alkes & Limbah B3) | D13: =SUMIFS(D4:D7, G4:G7, "Belum Dipotong (HIGH RISK)") -> 800000000 | E13: PPh 23 Tertunggak | F13: =SUMIFS(F4:F7, G4:G7, "Belum Dipotong (HIGH RISK)") -> 16000000 | G13: HIGH RISK | H13: Tinggi | I13: Potong susulan sebelum closing buku tahunan
A14: Total Sampel Transaksi Jasa Vendor PPh 23 | D14: =D12+D13 -> 4150000000 | E14: Total PPh 23 Terutang | F14: =F12+F13 -> 83000000 | I14: Total kewajiban PPh 23 dari 4 vendor sampel
A15: Saldo Utang PPh 23 pada Neraca Komersial (Kode 2-1300) | D15: ='Laporan Keuangan'!C40 -> 120000000 | E15: Status Akrual Neraca | G15: =IF('Laporan Keuangan'!C40>=F13, "Kewajiban Terakrual Cukup", "Kurang Akrual") -> Kewajiban Terakrual Cukup | I15: Saldo utang di neraca mencukupi paparan risiko
A16: Total Beban Jasa Medis & Operasional Terkait di Laba Rugi | D16: ='Laporan Keuangan'!C11+'Laporan Keuangan'!C12+'Laporan Keuangan'!C13 -> 6400000000 | E16: Beban Komersial 3 Akun | I16: Kalibrasi (2,4M) + Catering (2,2M) + Limbah (1,8M)
A17: Selisih Ekualisasi Objek PPh 23 vs Beban Laba Rugi | D17: =D16-D14 -> 2250000000 | E17: Belum Masuk Sampel | I17: Rekonsiliasi vendor-vendor pendukung lainnya

Sheet Dokumen Pendukung
A1: PT MEDIKA UTAMA SEJAHTERA (RS MEDIKA UTAMA)
A2: DOKUMEN PENDUKUNG REKONSILIASI FISKAL & MATRIKS MITIGASI KEPATUHAN PAJAK 2025
A3: A. KERTAS KERJA REKONSILIASI FISKAL (LABA RUGI KOMERSIAL KE FISKAL)
A4: No | B4: Pos / Akun Rekonsiliasi Fiskal | C4: Nilai (Rp) | D4: Jenis Koreksi | E4: Dasar Hukum / Regulasi Pajak | F4: Analisis Kepatuhan & Keterangan
A5: 1 | B5: Laba Bersih Komersial Sebelum Pajak | C5: ='Laporan Keuangan'!C20 -> 12800000000 | D5: Dasar Komersial | E5: Laporan Keuangan Audited/Unaudited | F5: Laba bersih operasional RS sebelum penyesuaian pajak
A6: 2 | B6: Koreksi Fiskal Positif:
A7: a | B7: Beban Cadangan Penurunan Nilai Piutang BPJS | C7: ='Laporan Keuangan'!C15 -> 2200000000 | D7: Positif (+) | E7: Pasal 9 ayat (1) huruf c UU PPh | F7: Pembentukan cadangan tidak diakui fiskal (non-deductible)
A8: b | B8: Beban Natura, Tempat Tinggal & Mobil Dokter | C8: ='Laporan Keuangan'!C16 -> 1450000000 | D8: Positif (+) | E8: PMK No. 66 Tahun 2023 | F8: Kenikmatan melebihi batasan bukan penunjang langsung keselamatan kerja
A9: 3 | B9: Total Koreksi Fiskal Positif | C9: =C7+C8 -> 3650000000 | D9: Subtotal Penambah | E9: Koreksi Positif Laba Fiskal | F9: Menambah penghasilan kena pajak badan
A10: 4 | B10: Koreksi Fiskal Negatif:
A11: a | B11: Pendapatan Sewa Kantin & Area Komersial | C11: ='Laporan Keuangan'!C6 -> 1500000000 | D11: Negatif (-) | E11: PP No. 34/2017 & Pasal 4 ayat (2) UU PPh | F11: Telah dipotong PPh Final 10% (dikeluarkan dari peredaran umum)
A12: 5 | B12: Total Koreksi Fiskal Negatif | C12: =C11 -> 1500000000 | D12: Subtotal Pengurang | E12: Koreksi Negatif Laba Fiskal | F12: Mengurangi laba komersial objek umum
A13: 6 | B13: Penghasilan Kena Pajak (PKP) / Laba Fiskal RS | C13: =C5+C9-C12 -> 14950000000 | D13: Net Fiskal | E13: Pasal 16 & Pasal 17 UU PPh / UU HPP | F13: Dasar perhitungan Pajak Penghasilan Badan Terutang
A14: 7 | B14: Estimasi PPh Badan Terutang (Tarif 22%) | C14: =C13*22% -> 3289000000 | D14: Kewajiban PPh Badan | E14: Pasal 17 ayat (1) huruf b UU PPh | F14: Estimasi pajak terutang tahun pajak 2025 sebelum kredit pajak
A16: B. RINGKASAN EKUALISASI PAJAK UTAMA VS LAPORAN KEUANGAN
A17: Jenis Pajak | B17: Nilai Objek di Laba Rugi (Rp) | C17: Nilai Sub-Ledger Terdata (Rp) | D17: Selisih Ekualisasi (Rp) | E17: Indikasi Saldo Neraca Terkait (Rp) | F17: Status Ekualisasi & Potensi Risiko | G17: Tindak Lanjut Sebelum SPT Tahunan
A18: PPh Pasal 21 (Dokter & SDM) | B18: ='Laporan Keuangan'!C8+'Laporan Keuangan'!C10 -> 32500000000 | C18: ='Sub-Ledger PPh 21 Dokter'!E10 -> 5700000000 | D18: =('Laporan Keuangan'!C8+'Laporan Keuangan'!C10)-'Sub-Ledger PPh 21 Dokter'!E10 -> 26800000000 | E18: ='Laporan Keuangan'!C39 -> 1150000000 | F18: Selisih bupot dokter mitra dan pegawai non-medis | G18: Ekualisasi menyeluruh 100% bupot 21 pegawai & dokter mitra
A19: PPN Farmasi / Penyerahan BKP | B19: ='Laporan Keuangan'!C4 -> 32000000000 | C19: ='Sub-Ledger PPN Farmasi'!D10 -> 188000000 | D19: ='Laporan Keuangan'!C4-'Sub-Ledger PPN Farmasi'!D10 -> 31812000000 | E19: ='Laporan Keuangan'!C41 -> 4800000000 | F19: Paparan risiko obat bebas OTC belum terbit faktur | G19: Terbitkan Faktur Pajak 010 atas penyerahan non-resep OTC
A20: PPh Pasal 23 (Jasa Vendor) | B20: ='Laporan Keuangan'!C11+'Laporan Keuangan'!C12+'Laporan Keuangan'!C13 -> 6400000000 | C20: ='Sub-Ledger PPh 23 Vendor'!D14 -> 4150000000 | D20: =B20-C20 -> 2250000000 | E20: ='Laporan Keuangan'!C40 -> 120000000 | F20: Terdapat 2 vendor belum dipotong PPh 23 Rp 16 Jt | G20: Penerbitan bukti potong unifikasi susulan & validasi SSP
A22: C. MATRIKS EVALUASI RISIKO & RENCANA AKSI KEPATUHAN (TAX ACTION MATRIX)
A23: No | B23: Area Perpajakan / Pos Keuangan | C23: Temuan & Indikasi Risiko | D23: Regulasi Acuan | E23: Eksposur Finansial / Pajak | F23: Langkah Mitigasi Prioritas | G23: Target Penyelesaian
A24: 1 | B24: Sub-Ledger PPh 21 Dokter | C24: Fasilitas top-up natura rumah dinas & kendaraan dokter mitra (Rp 133,6 Jt) belum dipotong PPh 21 | D24: PMK No. 168/2023 & PMK No. 66/2023 | E24: Potensi SKPKB PPh 21 + Sanksi Bunga Ps 13(2) KUP | F24: Hitung ulang DPP PPh 21 dengan memasukkan natura dan buat bukti potong pembetulan bupot 21 | G24: Sebelum Closing SPT Tahunan Badan
A25: 2 | B25: Sub-Ledger PPN Farmasi | C25: Penjualan obat bebas non-resep OTC (Rp 18 Jt) belum diterbitkan Faktur Pajak (High Risk) | D25: UU HPP & PMK No. 71/2022 | E25: Potensi Sanksi Bunga PPN 11% (Rp 1,98 Jt) + Denda FP Ps 14(4) KUP (1% DPP) | F25: Segera terbitkan Faktur Pajak elektronik (010) melalui e-Faktur dan setor PPN terutang | G25: Sebelum SPT Masa PPN periode berjalan dilaporkan
A26: 3 | B26: Sub-Ledger PPh 23 Vendor | C26: Tagihan kalibrasi alkes (PT Kalibrasi) & limbah B3 (CV EcoLimbah) belum dipotong PPh 23 (Rp 16 Jt) | D26: Pasal 23 UU PPh & PMK No. 141/2015 | E26: Potensi tanggungan pajak terutang Rp 16.000.000 + denda keterlambatan setor | F26: Kompensasikan potongan pada tagihan termin berikutnya atau terbitkan bukti potong unifikasi susulan | G26: Minggu ke-2 Januari 2026
A27: 4 | B27: Koreksi Fiskal Positif PPh Badan | C27: Beban cadangan piutang BPJS Rp 2,2M dan beban natura dokter Rp 1,45M wajib dikoreksi positif | D27: Pasal 9 ayat (1) huruf c UU PPh & PMK 66/2023 | E27: Kenaikan PKP sebesar Rp 3.650.000.000 (Potensi PPh Badan Rp 803.000.000) | F27: Lakukan rekonsiliasi fiskal positif pada Lampiran I SPT 1771 dan siapkan kertas kerja rincian per pos | G27: Penyusunan Draft SPT 1771
A28: 5 | B28: Keseimbangan Neraca Akuntansi | C28: Terdapat selisih Aset vs (Liabilitas + Ekuitas) sebesar Rp 14.420.000.000 pada neraca ringkas per 31 Des 2025 | D28: Standar Akuntansi Keuangan (SAK EP / PSAK) | E28: Distorsi laporan posisi keuangan dan ketidakwajaran saat audit eksternal / pemeriksa pajak | F28: Lakukan audit rekonsiliasi akun modal, laba ditahan komersial, dan piutang/utang akrual untuk menyeimbangkan neraca | G28: Audit Lapkeu Final 2025
A29: 6 | B29: Ekualisasi Omzet BPJS vs Faktur 080 | C29: Klaim BPJS Rp 28,5 Miliar perlu disinkronkan dengan rincian penyerahan paket obat & JKP Medis bebas PPN | D29: Pasal 16B UU PPN & PMK Jasa Kesehatan | E29: Risiko koreksi penyerahan bebas PPN jika dokumen pendukung klaim tidak lengkap | F29: Dokumentasikan FP Faktur 080 serta rekapitulasi berita acara verifikasi klaim BPJS Kesehatan | G29: Berkala Setiap Bulan
